2021-06-23 18:58:01,972 - instabot version: 0.117.0 (bot) - INFO - Instabot version: 0.117.0 Started
2021-06-23 18:58:01,983 - instabot version: 0.117.0 (bot) - DEBUG - Bot imported from C:\Users\hp\AppData\Local\Programs\Python\Python38-32\lib\site-packages\instabot\bot\bot.py
2021-06-23 18:58:01,986 - instabot version: 0.117.0 (api_login) - INFO - Not yet logged in starting: PRE-LOGIN FLOW!
2021-06-23 18:58:06,807 - instabot version: 0.117.0 (api) - DEBUG - POST to endpoint: accounts/get_prefill_candidates/ returned response: <Response [200]>
2021-06-23 18:58:09,184 - instabot version: 0.117.0 (api) - DEBUG - POST to endpoint: qe/sync/ returned response: <Response [200]>
2021-06-23 18:58:12,896 - instabot version: 0.117.0 (api) - DEBUG - POST to endpoint: launcher/sync/ returned response: <Response [200]>
2021-06-23 18:58:16,682 - instabot version: 0.117.0 (api) - DEBUG - POST to endpoint: accounts/contact_point_prefill/ returned response: <Response [200]>
2021-06-23 18:58:22,986 - instabot version: 0.117.0 (api) - DEBUG - POST to endpoint: accounts/login/ returned response: <Response [200]>
2021-06-23 18:58:22,988 - instabot version: 0.117.0 (api) - INFO - Logged-in successfully as 'taniya_verma_143'!
2021-06-23 18:58:22,989 - instabot version: 0.117.0 (api_login) - INFO - LOGIN FLOW! Just logged-in: True
2021-06-23 18:58:25,945 - instabot version: 0.117.0 (api) - DEBUG - POST to endpoint: qe/sync/ returned response: <Response [200]>
2021-06-23 18:58:29,263 - instabot version: 0.117.0 (api) - DEBUG - POST to endpoint: launcher/sync/ returned response: <Response [200]>
2021-06-23 18:58:31,897 - instabot version: 0.117.0 (api) - DEBUG - GET to endpoint: zr/token/result/?device_id=android-483dd0c6a985d9f6&token_hash=&custom_device_id=android-483dd0c6a985d9f6&fetch_reason=token_expired returned response: <Response [200]>
2021-06-23 18:58:36,236 - instabot version: 0.117.0 (api) - DEBUG - GET to endpoint: multiple_accounts/get_account_family/ returned response: <Response [200]>
2021-06-23 18:58:40,624 - instabot version: 0.117.0 (api) - DEBUG - POST to endpoint: qe/sync/ returned response: <Response [200]>
2021-06-23 18:58:43,865 - instabot version: 0.117.0 (api) - DEBUG - GET to endpoint: igtv/browse_feed/?prefetch=1 returned response: <Response [200]>
2021-06-23 18:58:45,400 - instabot version: 0.117.0 (api) - DEBUG - POST to endpoint: creatives/ar_class/ returned response: <Response [200]>
2021-06-23 18:58:48,582 - instabot version: 0.117.0 (api) - DEBUG - POST to endpoint: feed/reels_tray/ returned response: <Response [200]>
2021-06-23 18:58:53,422 - instabot version: 0.117.0 (api) - DEBUG - POST to endpoint: feed/timeline/ returned response: <Response [200]>
2021-06-23 18:58:57,473 - instabot version: 0.117.0 (api) - DEBUG - GET to endpoint: media/blocked/ returned response: <Response [200]>
2021-06-23 18:59:03,157 - instabot version: 0.117.0 (api) - DEBUG - GET to endpoint: news/inbox/ returned response: <Response [200]>
2021-06-23 18:59:06,514 - instabot version: 0.117.0 (api) - DEBUG - GET to endpoint: loom/fetch_config/ returned response: <Response [200]>
2021-06-23 18:59:10,065 - instabot version: 0.117.0 (api) - DEBUG - GET to endpoint: scores/bootstrap/users/?surfaces=["autocomplete_user_list","coefficient_besties_list_ranking","coefficient_rank_recipient_user_suggestion","coefficient_ios_section_test_bootstrap_ranking","coefficient_direct_recipients_ranking_variant_2"] returned response: <Response [200]>
2021-06-23 18:59:12,591 - instabot version: 0.117.0 (api) - DEBUG - GET to endpoint: business/eligibility/get_monetization_products_eligibility_data/?product_types=branded_content returned response: <Response [200]>
2021-06-23 18:59:15,894 - instabot version: 0.117.0 (api) - DEBUG - GET to endpoint: business/branded_content/should_require_professional_account/ returned response: <Response [200]>
2021-06-23 18:59:19,645 - instabot version: 0.117.0 (api) - DEBUG - GET to endpoint: linked_accounts/get_linkage_status/ returned response: <Response [200]>
2021-06-23 18:59:22,226 - instabot version: 0.117.0 (api) - DEBUG - GET to endpoint: locations/request_country/ returned response: <Response [200]>
2021-06-23 18:59:26,449 - instabot version: 0.117.0 (api) - DEBUG - GET to endpoint: qp/get_cooldowns/?signed_body=signed_body=4b9c516a5410a3bc128e09c6104a7f042146b9c2023870560c63a43a7f66781c.4&ig_sig_key_version=4&ig_sig_key_version=4 returned response: <Response [200]>
2021-06-23 18:59:32,987 - instabot version: 0.117.0 (api) - DEBUG - GET to endpoint: users/arlink_download_info/?version_override=2.2.1 returned response: <Response [200]>
2021-06-23 18:59:37,008 - instabot version: 0.117.0 (api) - DEBUG - GET to endpoint: users/48070542859/info/ returned response: <Response [200]>
2021-06-23 18:59:58,064 - instabot version: 0.117.0 (api) - WARNING - HTTPSConnectionPool(host='i.instagram.com', port=443): Max retries exceeded with url: /api/v1/direct_v2/get_presence/ (Caused by NewConnectionError('<urllib3.connection.HTTPSConnection object at 0x041EF400>: Failed to establish a new connection: [WinError 10060] A connection attempt failed because the connected party did not properly respond after a period of time, or established connection failed because connected host has failed to respond'))
2021-06-23 18:59:58,090 - instabot version: 0.117.0 (api) - WARNING - HTTPSConnectionPool(host='i.instagram.com', port=443): Max retries exceeded with url: /api/v1/direct_v2/inbox/?visual_message_return_type=unseen&thread_message_limit=10&persistentBadging=true&limit=20 (Caused by NewConnectionError('<urllib3.connection.HTTPSConnection object at 0x041EFEB0>: Failed to establish a new connection: [Errno 11001] getaddrinfo failed'))
2021-06-23 18:59:58,096 - instabot version: 0.117.0 (api) - WARNING - HTTPSConnectionPool(host='i.instagram.com', port=443): Max retries exceeded with url: /api/v1/direct_v2/inbox/?visual_message_return_type=unseen&persistentBadging=true&limit=0 (Caused by NewConnectionError('<urllib3.connection.HTTPSConnection object at 0x041EF988>: Failed to establish a new connection: [Errno 11001] getaddrinfo failed'))
2021-06-23 18:59:58,127 - instabot version: 0.117.0 (api) - WARNING - HTTPSConnectionPool(host='i.instagram.com', port=443): Max retries exceeded with url: /api/v1/discover/topical_explore/?is_prefetch=true&omit_cover_media=true&use_sectional_payload=true&timezone_offset=0&session_id=aaa96668-b134-4cf8-96ff-cee640764bd5&include_fixed_destinations=true (Caused by NewConnectionError('<urllib3.connection.HTTPSConnection object at 0x041EFBB0>: Failed to establish a new connection: [Errno 11001] getaddrinfo failed'))
2021-06-23 18:59:58,147 - instabot version: 0.117.0 (api) - WARNING - HTTPSConnectionPool(host='i.instagram.com', port=443): Max retries exceeded with url: /api/v1/notifications/badge/ (Caused by NewConnectionError('<urllib3.connection.HTTPSConnection object at 0x041EF4D8>: Failed to establish a new connection: [Errno 11001] getaddrinfo failed'))
2021-06-23 18:59:58,156 - instabot version: 0.117.0 (api) - WARNING - HTTPSConnectionPool(host='i.instagram.com', port=443): Max retries exceeded with url: /api/v1/qp/batch_fetch/ (Caused by NewConnectionError('<urllib3.connection.HTTPSConnection object at 0x041EF9B8>: Failed to establish a new connection: [Errno 11001] getaddrinfo failed'))
2021-06-23 18:59:58,158 - instabot version: 0.117.0 (bot_checkpoint) - DEBUG - Loading Checkpoint file from: C:\Users\hp\Desktop\Instagram/config/taniya_verma_143.checkpoint
2021-06-23 18:59:58,168 - instabot version: 0.117.0 (api) - WARNING - HTTPSConnectionPool(host='i.instagram.com', port=443): Max retries exceeded with url: /api/v1/users/saharsh_solanki_/usernameinfo/ (Caused by NewConnectionError('<urllib3.connection.HTTPSConnection object at 0x041EFE20>: Failed to establish a new connection: [Errno 11001] getaddrinfo failed'))
2021-06-23 18:59:58,959 - instabot version: 0.117.0 (bot_direct) - INFO - Going to send 1 messages.
2021-06-23 18:59:59,082 - instabot version: 0.117.0 (api) - WARNING - HTTPSConnectionPool(host='i.instagram.com', port=443): Max retries exceeded with url: /api/v1/direct_v2/threads/broadcast/text/ (Caused by NewConnectionError('<urllib3.connection.HTTPSConnection object at 0x04AA4A00>: Failed to establish a new connection: [Errno 11001] getaddrinfo failed'))
2021-06-23 18:59:59,084 - instabot version: 0.117.0 (bot_direct) - INFO - Message to ['48070542859'] wasn't sent
2021-06-23 19:00:09,122 - instabot version: 0.117.0 (api) - WARNING - HTTPSConnectionPool(host='i.instagram.com', port=443): Max retries exceeded with url: /api/v1/users/atwal7555/usernameinfo/ (Caused by NewConnectionError('<urllib3.connection.HTTPSConnection object at 0x04AA4868>: Failed to establish a new connection: [Errno 11001] getaddrinfo failed'))
2021-06-23 19:00:10,016 - instabot version: 0.117.0 (api) - WARNING - HTTPSConnectionPool(host='i.instagram.com', port=443): Max retries exceeded with url: /api/v1/users/48070542859/info/ (Caused by NewConnectionError('<urllib3.connection.HTTPSConnection object at 0x04AA4B98>: Failed to establish a new connection: [Errno 11001] getaddrinfo failed'))
2021-06-23 19:00:10,040 - instabot version: 0.117.0 (api) - WARNING - HTTPSConnectionPool(host='i.instagram.com', port=443): Max retries exceeded with url: /api/v1/friendships/48070542859/followers/?rank_token=48070542859_bc779281-696a-4198-a31f-facde373c9cc (Caused by NewConnectionError('<urllib3.connection.HTTPSConnection object at 0x04AA4AF0>: Failed to establish a new connection: [Errno 11001] getaddrinfo failed'))
2021-06-23 19:00:10,056 - instabot version: 0.117.0 (bot_checkpoint) - DEBUG - Saving Checkpoint file to: C:\Users\hp\Desktop\Instagram/config/taniya_verma_143.checkpoint
2021-06-23 19:00:10,060 - instabot version: 0.117.0 (bot) - INFO - Total messages: 2/69
2021-06-23 19:00:10,063 - instabot version: 0.117.0 (bot) - INFO - Total requests: 49
